Workbook
Name Locator: #REF!
Name Locator: 'Cap Table'!$LCB$524303

Sheet __FDSCACHE__
B1: This sheet contains FactSet XML data for use with this workbook's =FDS codes. Modifying the worksheet's contents may damage the workbook's =FDS functionality.

Sheet Master Inputs
A1: A.Brack
C2: Project MODEL - Master Inputs
C4: INSTRUCTIONS: | D4: 1. Enter data in Yellow (leave it blank if not relevant or not available).
D5: 2. Optional data enter in Light Blue cells.
C7: General
C8: Project Name: | D8: MODEL
C9: Model as of: | D9: =NOW() -> 46105.39
C10: Manager Director: | D10: MD name
D14: Legend:
D15: Clean all the input fields in the tab
D16: Clean all the input fields in the section
D17: Change Column's formulas position
C19: Remember to accept to 'UPDATE' the file and 'ENABLE CONTENT'.

Sheet Cap Table
A1: A.Brack
C2: Project MODEL - Capitalization Table
C3: Enter data in Yellow. Leave it blank if not relevant or not available. Optional data enter in Light Blue cells. | Q3: =K5 -> Seed
K4: Percentage Breakout | Q4: =K6 -> Series A
K5: =H13 -> Seed | L5: =(H$55+I$55)/$BY$55 -> #DIV/0! | M5: =BD13 -> Series E-1 | N5: =(BD55+BE55)/$BY$55 -> #DIV/0! | Q5: =K7 -> Series B
D6: Current Funding Series | E6: Seed | K6: =P13 -> Series A | L6: =(P$55+Q$55)/$BY$55 -> #DIV/0! | M6: =BL13 -> Series F | N6: =(J$55+K$55)/$BY$55 -> #DIV/0! | Q6: =K8 -> Series C
D7: ="DTC Investment in "&E6 -> DTC Investment in Seed | K7: =X13 -> Series B | L7: =(X$55+Y$55)/$BY$55 -> #DIV/0! | M7: =BT13 -> Series G | N7: =(BT55+BU55)/$BY$55 -> #DIV/0! | Q7: =K9 -> Series D
D8: Pre-Money Valuation | K8: =AF13 -> Series C | L8: =(AF$55+AG$55)/$BY$55 -> #DIV/0! | M8: Options | N8: =E$55/$BY$55 -> #DIV/0! | Q8: =K10 -> Series E
D9: ="Total "&E6&" Round" -> Total Seed Round | K9: =AN13 -> Series D | L9: =(AN$55+AO$55)/$BY$55 -> #DIV/0! | M9: Warrants | N9: =F$55/$BY$55 -> #DIV/0! | Q9: =M5 -> Series E-1
D10: Post-Money Valuation | E10: =IF(E6=H13,H16*M55,(IF(E6=P13,P16*U55,(IF(E6=X13,X16*AC55,(IF(E6=AF13,AF16*AK55,(IF(E6=AN13,AN16*AS55,(IF(E6=AV13,AV16*BA55,(IF(E6=BD13,BD16*BI55,(IF(E6=BL13,BL16*BQ55,(IF(E6=BT13,BT16*BY55,0))))))))))))))))) -> #DIV/0! | K10: =AV13 -> Series E | L10: =(AV$55+AW$55)/$BY$55 -> #DIV/0! | M10: Common | N10: =G$55/$BY$55 -> #DIV/0! | Q10: =M6 -> Series F
D11: Validation | E11: =IF(ROUND(E10,-2)=ROUND((E8+E9),-2),"Ok", "Review") -> #DIV/0! | Q11: =M7 -> Series G
H13: Seed | P13: Series A | X13: Series B | AF13: Series C | AN13: Series D | AV13: Series E | BD13: Series E-1 | BL13: Series F | BT13: Series G
H14: [Date] | P14: [Date] | X14: [Date] | AF14: [Date] | AN14: [Date] | AV14: [Date] | BD14: [Date] | BL14: [Date] | BT14: [Date]
E15: Options | F15: Warrants | G15: Common Stock | H15: =$H$13&" Prfrd" -> Seed Prfrd | I15: =$H$13&" Warrants" -> Seed Warrants | J15: =H13& " $$ Invested" -> Seed $$ Invested | K15: =$H$13&" Prfrd %" -> Seed Prfrd % | L15: Total Prfrd Shares | M15: Fully Diluted Shares | N15: % Total Prfrd | O15: % Fully Diluted | P15: =P13&" Prfrd" -> Series A Prfrd | Q15: =P13&" Warrants" -> Series A Warrants | R15: =P13& " $$ Invested" -> Series A $$ Invested | S15: =P13&" Prfrd %" -> Series A Prfrd % | T15: Total Prfrd Shares | U15: Fully Diluted Shares | V15: % Total Prfrd | W15: % Fully Diluted | X15: =X13&" Prfrd" -> Series B Prfrd | Y15: =X13&" Warrants" -> Series B Warrants | Z15: =X13& " $$ Invested" -> Series B $$ Invested | AA15: =X13&" Prfrd %" -> Series B Prfrd % | AB15: Total Prfrd Shares | AC15: Fully Diluted Shares | AD15: % Total Prfrd | AE15: % Fully Diluted | AF15: =AF13&" Prfrd" -> Series C Prfrd | AG15: =AF13&" Warrants" -> Series C Warrants | AH15: =AF13& " $$ Invested" -> Series C $$ Invested | AI15: =AF13&" Prfrd %" -> Series C Prfrd % | AJ15: Total Prfrd Shares | AK15: Fully Diluted Shares | AL15: % Total Prfrd | AM15: % Fully Diluted | AN15: =AN13&" Prfrd" -> Series D Prfrd | AO15: =AN13&" Warrants" -> Series D Warrants | AP15: =AN13& " $$ Invested" -> Series D $$ Invested | AQ15: =AN13&" Prfrd %" -> Series D Prfrd % | AR15: Total Prfrd Shares | AS15: Fully Diluted Shares | AT15: % Total Prfrd | AU15: % Fully Diluted | AV15: =AV13&" Prfrd" -> Series E Prfrd | AW15: =AV13&" Warrants" -> Series E Warrants | AX15: =AV13& " $$ Invested" -> Series E $$ Invested | AY15: =AV13&" Prfrd %" -> Series E Prfrd % | AZ15: Total Prfrd Shares | BA15: Fully Diluted Shares | BB15: % Total Prfrd | BC15: % Fully Diluted | BD15: =BD13&" Prfrd" -> Series E-1 Prfrd | BE15: =BD13&" Warrants" -> Series E-1 Warrants | BF15: =BD13& " $$ Invested" -> Series E-1 $$ Invested | BG15: =BD13&" Prfrd %" -> Series E-1 Prfrd % | BH15: Total Prfrd Shares | BI15: Fully Diluted Shares | BJ15: % Total Prfrd | BK15: % Fully Diluted | BL15: =BL13&" Prfrd" -> Series F Prfrd | BM15: =BL13&" Warrants" -> Series F Warrants | BN15: =BL13& " $$ Invested" -> Series F $$ Invested | BO15: =BL13&" Prfrd %" -> Series F Prfrd % | BP15: Total Prfrd Shares | BQ15: Fully Diluted Shares | BR15: % Total Prfrd | BS15: % Fully Diluted | BT15: =BT13&" Prfrd" -> Series G Prfrd | BU15: =BT13&" Warrants" -> Series G Warrants | BV15: =BT13& " $$ Invested" -> Series G $$ Invested | BW15: =BT13&" Prfrd %" -> Series G Prfrd % | BX15: Total Prfrd Shares | BY15: Fully Diluted Shares | BZ15: % Total Prfrd | CA15: % Fully Diluted | CC15: TOTAL $$ INVESTED
C16: 1 | D16: Issue Price | H16: =IF(H13=$E$6,$E$8/G55,) -> #DIV/0! | I16: =H16 -> #DIV/0! | P16: =IF(P13=$E$6,$E$8/M55,) -> 0 | Q16: =P16 -> 0 | X16: =IF(X13=$E$6,$E$8/U55,) -> 0 | Y16: =X16 -> 0 | AF16: =IF(AF13=$E$6,$E$8/AC55,) -> 0 | AG16: =AF16 -> 0 | AN16: =IF(AN13=$E$6,$E$8/AK55,) -> 0 | AO16: =AN16 -> 0 | AV16: =IF(AV13=$E$6,$E$8/AS55,) -> 0 | AW16: =AV16 -> 0 | BD16: =IF(BD13=$E$6,$E$8/BA55,) -> 0 | BE16: =BD16 -> 0 | BL16: =IF(BL13=$E$6,$E$8/BI55,) -> 0 | BM16: =BL16 -> 0 | BT16: =IF(BT13=$E$6,$E$8/BQ55,) -> 0 | BU16: =BT16 -> 0
C17: 2 | D17: Liquidation Preference Multiple | H17: 1 | P17: 1 | X17: 1 | AF17: 1 | AN17: 1 | AV17: 1 | BD17: 1 | BL17: 1 | BT17: 1
C18: 3 | D18: Seniority Rank | H18: 3 | P18: 3 | X18: 3 | AF18: 3 | AN18: 3 | AV18: 3 | BD18: 3 | BL18: 3 | BT18: 3
D20: Dell Technologies Capital | J20: =H20*H$16+I20*I$16 -> #DIV/0! | K20: =IF(H20=0,0,H20/H$55) -> 0 | L20: =$H20 -> 0 | M20: =SUM($E20:$G20)+$H20+$I20 -> 0 | N20: =L20/L$55 -> #DIV/0! | O20: =M20/M$55 -> #DIV/0! | R20: =P20*P$16+Q20*Q$16 -> 0 | S20: =IF(P20=0,0,P20/P$55) -> 0 | T20: =L20+P20 -> 0 | U20: =M20+P20+Q20 -> 0 | V20: =T20/T$55 -> #DIV/0! | W20: =U20/U$55 -> #DIV/0! | Z20: =X20*X$16+Y20*Y$16 -> 0 | AA20: =IF(X20=0,0,X20/X$55) -> 0 | AB20: =T20+X20 -> 0 | AC20: =U20+X20+Y20 -> 0 | AD20: =AB20/AB$55 -> #DIV/0! | AE20: =AC20/AC$55 -> #DIV/0! | AH20: =AF20*AF$16+AG20*AG$16 -> 0 | AI20: =IF(AF20=0,0,AF20/AF$55) -> 0 | AJ20: =AB20+AF20 -> 0 | AK20: =AC20+AF20+AG20 -> 0 | AL20: =AJ20/AJ$55 -> #DIV/0! | AM20: =AK20/AK$55 -> #DIV/0! | AP20: =AN20*AN$16+AO20*AO$16 -> 0 | AQ20: =IF(AN20=0,0,AN20/AN$55) -> 0 | AR20: =AJ20+AN20 -> 0 | AS20: =AK20+AN20+AO20 -> 0 | AT20: =AR20/AR$55 -> #DIV/0! | AU20: =AS20/AS$55 -> #DIV/0! | AX20: =AV20*AV$16+AW20*AW$16 -> 0 | AY20: =IF(AV20=0,0,AV20/AV$55) -> 0 | AZ20: =AR20+AV20 -> 0 | BA20: =AS20+AV20+AW20 -> 0 | BB20: =AZ20/AZ$55 -> #DIV/0! | BC20: =BA20/BA$55 -> #DIV/0! | BF20: =BD20*BD$16+BE20*BE$16 -> 0 | BG20: =IF(BD20=0,0,BD20/BD$55) -> 0 | BH20: =AZ20+BD20 -> 0 | BI20: =BA20+BD20+BE20 -> 0 | BJ20: =BH20/BH$55 -> #DIV/0! | BK20: =BI20/BI$55 -> #DIV/0! | BN20: =BL20*BL$16+BM20*BM$16 -> 0 | BO20: =IF(BL20=0,0,BL20/BL$55) -> 0 | BP20: =BH20+BL20 -> 0 | BQ20: =BI20+BL20+BM20 -> 0 | BR20: =BP20/BP$55 -> #DIV/0! | BS20: =BQ20/BQ$55 -> #DIV/0! | BV20: =BT20*BT$16+BU20*BU$16 -> 0 | BW20: =IF(BT20=0,0,BT20/BT$55) -> 0 | BX20: =BP20+BT20 -> 0 | BY20: =BQ20+BT20+BU20 -> 0 | BZ20: =BX20/BX$55 -> #DIV/0! | CA20: =BY20/BY$55 -> #DIV/0! | CC20: =SUM(J20,R20,Z20,AH20,AP20,AX20,BF20,BN20,BV20) -> #DIV/0!
D21: Investor 1 | J21: =H21*H$16+I21*I$16 -> #DIV/0! | K21: =IF(H21=0,0,H21/H$55) -> 0 | L21: =$H21 -> 0 | M21: =IF(SUM($E21:$G21)+$H21+$I21=0,,SUM($E21:$G21)+$H21+$I21) -> 0 | N21: =L21/L$55 -> #DIV/0! | O21: =M21/M$55 -> #DIV/0! | R21: =P21*P$16+Q21*Q$16 -> 0 | S21: =IF(P21=0,0,P21/P$55) -> 0 | T21: =L21+P21 -> 0 | U21: =M21+P21+Q21 -> 0 | V21: =T21/T$55 -> #DIV/0! | W21: =U21/U$55 -> #DIV/0! | Z21: =X21*X$16+Y21*Y$16 -> 0 | AA21: =IF(X21=0,0,X21/X$55) -> 0 | AB21: =T21+X21 -> 0 | AC21: =U21+X21+Y21 -> 0 | AD21: =AB21/AB$55 -> #DIV/0! | AE21: =AC21/AC$55 -> #DIV/0! | AH21: =AF21*AF$16+AG21*AG$16 -> 0 | AI21: =IF(AF21=0,0,AF21/AF$55) -> 0 | AJ21: =AB21+AF21 -> 0 | AK21: =AC21+AF21+AG21 -> 0 | AL21: =AJ21/AJ$55 -> #DIV/0! | AM21: =AK21/AK$55 -> #DIV/0! | AP21: =AN21*AN$16+AO21*AO$16 -> 0 | AQ21: =IF(AN21=0,0,AN21/AN$55) -> 0 | AR21: =AJ21+AN21 -> 0 | AS21: =AK21+AN21+AO21 -> 0 | AT21: =AR21/AR$55 -> #DIV/0! | AU21: =AS21/AS$55 -> #DIV/0! | AX21: =AV21*AV$16+AW21*AW$16 -> 0 | AY21: =IF(AV21=0,0,AV21/AV$55) -> 0 | AZ21: =AR21+AV21 -> 0 | BA21: =AS21+AV21+AW21 -> 0 | BB21: =AZ21/AZ$55 -> #DIV/0! | BC21: =BA21/BA$55 -> #DIV/0! | BF21: =BD21*BD$16+BE21*BE$16 -> 0 | BG21: =IF(BD21=0,0,BD21/BD$55) -> 0 | BH21: =AZ21+BD21 -> 0 | BI21: =BA21+BD21+BE21 -> 0 | BJ21: =BH21/BH$55 -> #DIV/0! | BK21: =BI21/BI$55 -> #DIV/0! | BN21: =BL21*BL$16+BM21*BM$16 -> 0 | BO21: =IF(BL21=0,0,BL21/BL$55) -> 0 | BP21: =BH21+BL21 -> 0 | BQ21: =BI21+BL21+BM21 -> 0 | BR21: =BP21/BP$55 -> #DIV/0! | BS21: =BQ21/BQ$55 -> #DIV/0! | BV21: =BT21*BT$16+BU21*BU$16 -> 0 | BW21: =IF(BT21=0,0,BT21/BT$55) -> 0 | BX21: =BP21+BT21 -> 0 | BY21: =BQ21+BT21+BU21 -> 0 | BZ21: =BX21/BX$55 -> #DIV/0! | CA21: =BY21/BY$55 -> #DIV/0! | CC21: =SUM(J21,R21,Z21,AH21,AP21,AX21,BF21,BN21,BV21) -> #DIV/0!
D22: Investor 2 | J22: =H22*H$16+I22*I$16 -> #DIV/0! | K22: =IF(H22=0,0,H22/H$55) -> 0 | L22: =$H22 -> 0 | M22: =IF(SUM($E22:$G22)+$H22+$I22=0,,SUM($E22:$G22)+$H22+$I22) -> 0 | N22: =L22/L$55 -> #DIV/0! | O22: =M22/M$55 -> #DIV/0! | R22: =P22*P$16+Q22*Q$16 -> 0 | S22: =IF(P22=0,0,P22/P$55) -> 0 | T22: =L22+P22 -> 0 | U22: =M22+P22+Q22 -> 0 | V22: =T22/T$55 -> #DIV/0! | W22: =U22/U$55 -> #DIV/0! | Z22: =X22*X$16+Y22*Y$16 -> 0 | AA22: =IF(X22=0,0,X22/X$55) -> 0 | AB22: =T22+X22 -> 0 | AC22: =U22+X22+Y22 -> 0 | AD22: =AB22/AB$55 -> #DIV/0! | AE22: =AC22/AC$55 -> #DIV/0! | AH22: =AF22*AF$16+AG22*AG$16 -> 0 | AI22: =IF(AF22=0,0,AF22/AF$55) -> 0 | AJ22: =AB22+AF22 -> 0 | AK22: =AC22+AF22+AG22 -> 0 | AL22: =AJ22/AJ$55 -> #DIV/0! | AM22: =AK22/AK$55 -> #DIV/0! | AP22: =AN22*AN$16+AO22*AO$16 -> 0 | AQ22: =IF(AN22=0,0,AN22/AN$55) -> 0 | AR22: =AJ22+AN22 -> 0 | AS22: =AK22+AN22+AO22 -> 0 | AT22: =AR22/AR$55 -> #DIV/0! | AU22: =AS22/AS$55 -> #DIV/0! | AX22: =AV22*AV$16+AW22*AW$16 -> 0 | AY22: =IF(AV22=0,0,AV22/AV$55) -> 0 | AZ22: =AR22+AV22 -> 0 | BA22: =AS22+AV22+AW22 -> 0 | BB22: =AZ22/AZ$55 -> #DIV/0! | BC22: =BA22/BA$55 -> #DIV/0! | BF22: =BD22*BD$16+BE22*BE$16 -> 0 | BG22: =IF(BD22=0,0,BD22/BD$55) -> 0 | BH22: =AZ22+BD22 -> 0 | BI22: =BA22+BD22+BE22 -> 0 | BJ22: =BH22/BH$55 -> #DIV/0! | BK22: =BI22/BI$55 -> #DIV/0! | BN22: =BL22*BL$16+BM22*BM$16 -> 0 | BO22: =IF(BL22=0,0,BL22/BL$55) -> 0 | BP22: =BH22+BL22 -> 0 | BQ22: =BI22+BL22+BM22 -> 0 | BR22: =BP22/BP$55 -> #DIV/0! | BS22: =BQ22/BQ$55 -> #DIV/0! | BV22: =BT22*BT$16+BU22*BU$16 -> 0 | BW22: =IF(BT22=0,0,BT22/BT$55) -> 0 | BX22: =BP22+BT22 -> 0 | BY22: =BQ22+BT22+BU22 -> 0 | BZ22: =BX22/BX$55 -> #DIV/0! | CA22: =BY22/BY$55 -> #DIV/0! | CC22: =SUM(J22,R22,Z22,AH22,AP22,AX22,BF22,BN22,BV22) -> #DIV/0!
D23: Investor 3 | J23: =H23*H$16+I23*I$16 -> #DIV/0! | K23: =IF(H23=0,0,H23/H$55) -> 0 | L23: =$H23 -> 0 | M23: =IF(SUM($E23:$G23)+$H23+$I23=0,,SUM($E23:$G23)+$H23+$I23) -> 0 | N23: =L23/L$55 -> #DIV/0! | O23: =M23/M$55 -> #DIV/0! | R23: =P23*P$16+Q23*Q$16 -> 0 | S23: =IF(P23=0,0,P23/P$55) -> 0 | T23: =L23+P23 -> 0 | U23: =M23+P23+Q23 -> 0 | V23: =T23/T$55 -> #DIV/0! | W23: =U23/U$55 -> #DIV/0! | Z23: =X23*X$16+Y23*Y$16 -> 0 | AA23: =IF(X23=0,0,X23/X$55) -> 0 | AB23: =T23+X23 -> 0 | AC23: =U23+X23+Y23 -> 0 | AD23: =AB23/AB$55 -> #DIV/0! | AE23: =AC23/AC$55 -> #DIV/0! | AH23: =AF23*AF$16+AG23*AG$16 -> 0 | AI23: =IF(AF23=0,0,AF23/AF$55) -> 0 | AJ23: =AB23+AF23 -> 0 | AK23: =AC23+AF23+AG23 -> 0 | AL23: =AJ23/AJ$55 -> #DIV/0! | AM23: =AK23/AK$55 -> #DIV/0! | AP23: =AN23*AN$16+AO23*AO$16 -> 0 | AQ23: =IF(AN23=0,0,AN23/AN$55) -> 0 | AR23: =AJ23+AN23 -> 0 | AS23: =AK23+AN23+AO23 -> 0 | AT23: =AR23/AR$55 -> #DIV/0! | AU23: =AS23/AS$55 -> #DIV/0! | AX23: =AV23*AV$16+AW23*AW$16 -> 0 | AY23: =IF(AV23=0,0,AV23/AV$55) -> 0 | AZ23: =AR23+AV23 -> 0 | BA23: =AS23+AV23+AW23 -> 0 | BB23: =AZ23/AZ$55 -> #DIV/0! | BC23: =BA23/BA$55 -> #DIV/0! | BF23: =BD23*BD$16+BE23*BE$16 -> 0 | BG23: =IF(BD23=0,0,BD23/BD$55) -> 0 | BH23: =AZ23+BD23 -> 0 | BI23: =BA23+BD23+BE23 -> 0 | BJ23: =BH23/BH$55 -> #DIV/0! | BK23: =BI23/BI$55 -> #DIV/0! | BN23: =BL23*BL$16+BM23*BM$16 -> 0 | BO23: =IF(BL23=0,0,BL23/BL$55) -> 0 | BP23: =BH23+BL23 -> 0 | BQ23: =BI23+BL23+BM23 -> 0 | BR23: =BP23/BP$55 -> #DIV/0! | BS23: =BQ23/BQ$55 -> #DIV/0! | BV23: =BT23*BT$16+BU23*BU$16 -> 0 | BW23: =IF(BT23=0,0,BT23/BT$55) -> 0 | BX23: =BP23+BT23 -> 0 | BY23: =BQ23+BT23+BU23 -> 0 | BZ23: =BX23/BX$55 -> #DIV/0! | CA23: =BY23/BY$55 -> #DIV/0! | CC23: =SUM(J23,R23,Z23,AH23,AP23,AX23,BF23,BN23,BV23) -> #DIV/0!
D24: Investor 4 | J24: =H24*H$16+I24*I$16 -> #DIV/0! | K24: =IF(H24=0,0,H24/H$55) -> 0 | L24: =$H24 -> 0 | M24: =IF(SUM($E24:$G24)+$H24+$I24=0,,SUM($E24:$G24)+$H24+$I24) -> 0 | N24: =L24/L$55 -> #DIV/0! | O24: =M24/M$55 -> #DIV/0! | R24: =P24*P$16+Q24*Q$16 -> 0 | S24: =IF(P24=0,0,P24/P$55) -> 0 | T24: =L24+P24 -> 0 | U24: =M24+P24+Q24 -> 0 | V24: =T24/T$55 -> #DIV/0! | W24: =U24/U$55 -> #DIV/0! | Z24: =X24*X$16+Y24*Y$16 -> 0 | AA24: =IF(X24=0,0,X24/X$55) -> 0 | AB24: =T24+X24 -> 0 | AC24: =U24+X24+Y24 -> 0 | AD24: =AB24/AB$55 -> #DIV/0! | AE24: =AC24/AC$55 -> #DIV/0! | AH24: =AF24*AF$16+AG24*AG$16 -> 0 | AI24: =IF(AF24=0,0,AF24/AF$55) -> 0 | AJ24: =AB24+AF24 -> 0 | AK24: =AC24+AF24+AG24 -> 0 | AL24: =AJ24/AJ$55 -> #DIV/0! | AM24: =AK24/AK$55 -> #DIV/0! | AP24: =AN24*AN$16+AO24*AO$16 -> 0 | AQ24: =IF(AN24=0,0,AN24/AN$55) -> 0 | AR24: =AJ24+AN24 -> 0 | AS24: =AK24+AN24+AO24 -> 0 | AT24: =AR24/AR$55 -> #DIV/0! | AU24: =AS24/AS$55 -> #DIV/0! | AX24: =AV24*AV$16+AW24*AW$16 -> 0 | AY24: =IF(AV24=0,0,AV24/AV$55) -> 0 | AZ24: =AR24+AV24 -> 0 | BA24: =AS24+AV24+AW24 -> 0 | BB24: =AZ24/AZ$55 -> #DIV/0! | BC24: =BA24/BA$55 -> #DIV/0! | BF24: =BD24*BD$16+BE24*BE$16 -> 0 | BG24: =IF(BD24=0,0,BD24/BD$55) -> 0 | BH24: =AZ24+BD24 -> 0 | BI24: =BA24+BD24+BE24 -> 0 | BJ24: =BH24/BH$55 -> #DIV/0! | BK24: =BI24/BI$55 -> #DIV/0! | BN24: =BL24*BL$16+BM24*BM$16 -> 0 | BO24: =IF(BL24=0,0,BL24/BL$55) -> 0 | BP24: =BH24+BL24 -> 0 | BQ24: =BI24+BL24+BM24 -> 0 | BR24: =BP24/BP$55 -> #DIV/0! | BS24: =BQ24/BQ$55 -> #DIV/0! | BV24: =BT24*BT$16+BU24*BU$16 -> 0 | BW24: =IF(BT24=0,0,BT24/BT$55) -> 0 | BX24: =BP24+BT24 -> 0 | BY24: =BQ24+BT24+BU24 -> 0 | BZ24: =BX24/BX$55 -> #DIV/0! | CA24: =BY24/BY$55 -> #DIV/0! | CC24: =SUM(J24,R24,Z24,AH24,AP24,AX24,BF24,BN24,BV24) -> #DIV/0!
D25: Investor 5 | J25: =H25*H$16+I25*I$16 -> #DIV/0! | K25: =IF(H25=0,0,H25/H$55) -> 0 | L25: =$H25 -> 0 | M25: =IF(SUM($E25:$G25)+$H25+$I25=0,,SUM($E25:$G25)+$H25+$I25) -> 0 | N25: =L25/L$55 -> #DIV/0! | O25: =M25/M$55 -> #DIV/0! | R25: =P25*P$16+Q25*Q$16 -> 0 | S25: =IF(P25=0,0,P25/P$55) -> 0 | T25: =L25+P25 -> 0 | U25: =M25+P25+Q25 -> 0 | V25: =T25/T$55 -> #DIV/0! | W25: =U25/U$55 -> #DIV/0! | Z25: =X25*X$16+Y25*Y$16 -> 0 | AA25: =IF(X25=0,0,X25/X$55) -> 0 | AB25: =T25+X25 -> 0 | AC25: =U25+X25+Y25 -> 0 | AD25: =AB25/AB$55 -> #DIV/0! | AE25: =AC25/AC$55 -> #DIV/0! | AH25: =AF25*AF$16+AG25*AG$16 -> 0 | AI25: =IF(AF25=0,0,AF25/AF$55) -> 0 | AJ25: =AB25+AF25 -> 0 | AK25: =AC25+AF25+AG25 -> 0 | AL25: =AJ25/AJ$55 -> #DIV/0! | AM25: =AK25/AK$55 -> #DIV/0! | AP25: =AN25*AN$16+AO25*AO$16 -> 0 | AQ25: =IF(AN25=0,0,AN25/AN$55) -> 0 | AR25: =AJ25+AN25 -> 0 | AS25: =AK25+AN25+AO25 -> 0 | AT25: =AR25/AR$55 -> #DIV/0! | AU25: =AS25/AS$55 -> #DIV/0! | AX25: =AV25*AV$16+AW25*AW$16 -> 0 | AY25: =IF(AV25=0,0,AV25/AV$55) -> 0 | AZ25: =AR25+AV25 -> 0 | BA25: =AS25+AV25+AW25 -> 0 | BB25: =AZ25/AZ$55 -> #DIV/0! | BC25: =BA25/BA$55 -> #DIV/0! | BF25: =BD25*BD$16+BE25*BE$16 -> 0 | BG25: =IF(BD25=0,0,BD25/BD$55) -> 0 | BH25: =AZ25+BD25 -> 0 | BI25: =BA25+BD25+BE25 -> 0 | BJ25: =BH25/BH$55 -> #DIV/0! | BK25: =BI25/BI$55 -> #DIV/0! | BN25: =BL25*BL$16+BM25*BM$16 -> 0 | BO25: =IF(BL25=0,0,BL25/BL$55) -> 0 | BP25: =BH25+BL25 -> 0 | BQ25: =BI25+BL25+BM25 -> 0 | BR25: =BP25/BP$55 -> #DIV/0! | BS25: =BQ25/BQ$55 -> #DIV/0! | BV25: =BT25*BT$16+BU25*BU$16 -> 0 | BW25: =IF(BT25=0,0,BT25/BT$55) -> 0 | BX25: =BP25+BT25 -> 0 | BY25: =BQ25+BT25+BU25 -> 0 | BZ25: =BX25/BX$55 -> #DIV/0! | CA25: =BY25/BY$55 -> #DIV/0! | CC25: =SUM(J25,R25,Z25,AH25,AP25,AX25,BF25,BN25,BV25) -> #DIV/0!
D26: Investor 6 | J26: =H26*H$16+I26*I$16 -> #DIV/0! | K26: =IF(H26=0,0,H26/H$55) -> 0 | L26: =$H26 -> 0 | M26: =IF(SUM($E26:$G26)+$H26+$I26=0,,SUM($E26:$G26)+$H26+$I26) -> 0 | N26: =L26/L$55 -> #DIV/0! | O26: =M26/M$55 -> #DIV/0! | R26: =P26*P$16+Q26*Q$16 -> 0 | S26: =IF(P26=0,0,P26/P$55) -> 0 | T26: =L26+P26 -> 0 | U26: =M26+P26+Q26 -> 0 | V26: =T26/T$55 -> #DIV/0! | W26: =U26/U$55 -> #DIV/0! | Z26: =X26*X$16+Y26*Y$16 -> 0 | AA26: =IF(X26=0,0,X26/X$55) -> 0 | AB26: =T26+X26 -> 0 | AC26: =U26+X26+Y26 -> 0 | AD26: =AB26/AB$55 -> #DIV/0! | AE26: =AC26/AC$55 -> #DIV/0! | AH26: =AF26*AF$16+AG26*AG$16 -> 0 | AI26: =IF(AF26=0,0,AF26/AF$55) -> 0 | AJ26: =AB26+AF26 -> 0 | AK26: =AC26+AF26+AG26 -> 0 | AL26: =AJ26/AJ$55 -> #DIV/0! | AM26: =AK26/AK$55 -> #DIV/0! | AP26: =AN26*AN$16+AO26*AO$16 -> 0 | AQ26: =IF(AN26=0,0,AN26/AN$55) -> 0 | AR26: =AJ26+AN26 -> 0 | AS26: =AK26+AN26+AO26 -> 0 | AT26: =AR26/AR$55 -> #DIV/0! | AU26: =AS26/AS$55 -> #DIV/0! | AX26: =AV26*AV$16+AW26*AW$16 -> 0 | AY26: =IF(AV26=0,0,AV26/AV$55) -> 0 | AZ26: =AR26+AV26 -> 0 | BA26: =AS26+AV26+AW26 -> 0 | BB26: =AZ26/AZ$55 -> #DIV/0! | BC26: =BA26/BA$55 -> #DIV/0! | BF26: =BD26*BD$16+BE26*BE$16 -> 0 | BG26: =IF(BD26=0,0,BD26/BD$55) -> 0 | BH26: =AZ26+BD26 -> 0 | BI26: =BA26+BD26+BE26 -> 0 | BJ26: =BH26/BH$55 -> #DIV/0! | BK26: =BI26/BI$55 -> #DIV/0! | BN26: =BL26*BL$16+BM26*BM$16 -> 0 | BO26: =IF(BL26=0,0,BL26/BL$55) -> 0 | BP26: =BH26+BL26 -> 0 | BQ26: =BI26+BL26+BM26 -> 0 | BR26: =BP26/BP$55 -> #DIV/0! | BS26: =BQ26/BQ$55 -> #DIV/0! | BV26: =BT26*BT$16+BU26*BU$16 -> 0 | BW26: =IF(BT26=0,0,BT26/BT$55) -> 0 | BX26: =BP26+BT26 -> 0 | BY26: =BQ26+BT26+BU26 -> 0 | BZ26: =BX26/BX$55 -> #DIV/0! | CA26: =BY26/BY$55 -> #DIV/0! | CC26: =SUM(J26,R26,Z26,AH26,AP26,AX26,BF26,BN26,BV26) -> #DIV/0!
D27: Investor 7 | J27: =H27*H$16+I27*I$16 -> #DIV/0! | K27: =IF(H27=0,0,H27/H$55) -> 0 | L27: =$H27 -> 0 | M27: =IF(SUM($E27:$G27)+$H27+$I27=0,,SUM($E27:$G27)+$H27+$I27) -> 0 | N27: =L27/L$55 -> #DIV/0! | O27: =M27/M$55 -> #DIV/0! | R27: =P27*P$16+Q27*Q$16 -> 0 | S27: =IF(P27=0,0,P27/P$55) -> 0 | T27: =L27+P27 -> 0 | U27: =M27+P27+Q27 -> 0 | V27: =T27/T$55 -> #DIV/0! | W27: =U27/U$55 -> #DIV/0! | Z27: =X27*X$16+Y27*Y$16 -> 0 | AA27: =IF(X27=0,0,X27/X$55) -> 0 | AB27: =T27+X27 -> 0 | AC27: =U27+X27+Y27 -> 0 | AD27: =AB27/AB$55 -> #DIV/0! | AE27: =AC27/AC$55 -> #DIV/0! | AH27: =AF27*AF$16+AG27*AG$16 -> 0 | AI27: =IF(AF27=0,0,AF27/AF$55) -> 0 | AJ27: =AB27+AF27 -> 0 | AK27: =AC27+AF27+AG27 -> 0 | AL27: =AJ27/AJ$55 -> #DIV/0! | AM27: =AK27/AK$55 -> #DIV/0! | AP27: =AN27*AN$16+AO27*AO$16 -> 0 | AQ27: =IF(AN27=0,0,AN27/AN$55) -> 0 | AR27: =AJ27+AN27 -> 0 | AS27: =AK27+AN27+AO27 -> 0 | AT27: =AR27/AR$55 -> #DIV/0! | AU27: =AS27/AS$55 -> #DIV/0! | AX27: =AV27*AV$16+AW27*AW$16 -> 0 | AY27: =IF(AV27=0,0,AV27/AV$55) -> 0 | AZ27: =AR27+AV27 -> 0 | BA27: =AS27+AV27+AW27 -> 0 | BB27: =AZ27/AZ$55 -> #DIV/0! | BC27: =BA27/BA$55 -> #DIV/0! | BF27: =BD27*BD$16+BE27*BE$16 -> 0 | BG27: =IF(BD27=0,0,BD27/BD$55) -> 0 | BH27: =AZ27+BD27 -> 0 | BI27: =BA27+BD27+BE27 -> 0 | BJ27: =BH27/BH$55 -> #DIV/0! | BK27: =BI27/BI$55 -> #DIV/0! | BN27: =BL27*BL$16+BM27*BM$16 -> 0 | BO27: =IF(BL27=0,0,BL27/BL$55) -> 0 | BP27: =BH27+BL27 -> 0 | BQ27: =BI27+BL27+BM27 -> 0 | BR27: =BP27/BP$55 -> #DIV/0! | BS27: =BQ27/BQ$55 -> #DIV/0! | BV27: =BT27*BT$16+BU27*BU$16 -> 0 | BW27: =IF(BT27=0,0,BT27/BT$55) -> 0 | BX27: =BP27+BT27 -> 0 | BY27: =BQ27+BT27+BU27 -> 0 | BZ27: =BX27/BX$55 -> #DIV/0! | CA27: =BY27/BY$55 -> #DIV/0! | CC27: =SUM(J27,R27,Z27,AH27,AP27,AX27,BF27,BN27,BV27) -> #DIV/0!
D28: Investor 8 | J28: =H28*H$16+I28*I$16 -> #DIV/0! | K28: =IF(H28=0,0,H28/H$55) -> 0 | L28: =$H28 -> 0 | M28: =IF(SUM($E28:$G28)+$H28+$I28=0,,SUM($E28:$G28)+$H28+$I28) -> 0 | N28: =L28/L$55 -> #DIV/0! | O28: =M28/M$55 -> #DIV/0! | R28: =P28*P$16+Q28*Q$16 -> 0 | S28: =IF(P28=0,0,P28/P$55) -> 0 | T28: =L28+P28 -> 0 | U28: =M28+P28+Q28 -> 0 | V28: =T28/T$55 -> #DIV/0! | W28: =U28/U$55 -> #DIV/0! | Z28: =X28*X$16+Y28*Y$16 -> 0 | AA28: =IF(X28=0,0,X28/X$55) -> 0 | AB28: =T28+X28 -> 0 | AC28: =U28+X28+Y28 -> 0 | AD28: =AB28/AB$55 -> #DIV/0! | AE28: =AC28/AC$55 -> #DIV/0! | AH28: =AF28*AF$16+AG28*AG$16 -> 0 | AI28: =IF(AF28=0,0,AF28/AF$55) -> 0 | AJ28: =AB28+AF28 -> 0 | AK28: =AC28+AF28+AG28 -> 0 | AL28: =AJ28/AJ$55 -> #DIV/0! | AM28: =AK28/AK$55 -> #DIV/0! | AP28: =AN28*AN$16+AO28*AO$16 -> 0 | AQ28: =IF(AN28=0,0,AN28/AN$55) -> 0 | AR28: =AJ28+AN28 -> 0 | AS28: =AK28+AN28+AO28 -> 0 | AT28: =AR28/AR$55 -> #DIV/0! | AU28: =AS28/AS$55 -> #DIV/0! | AX28: =AV28*AV$16+AW28*AW$16 -> 0 | AY28: =IF(AV28=0,0,AV28/AV$55) -> 0 | AZ28: =AR28+AV28 -> 0 | BA28: =AS28+AV28+AW28 -> 0 | BB28: =AZ28/AZ$55 -> #DIV/0! | BC28: =BA28/BA$55 -> #DIV/0! | BF28: =BD28*BD$16+BE28*BE$16 -> 0 | BG28: =IF(BD28=0,0,BD28/BD$55) -> 0 | BH28: =AZ28+BD28 -> 0 | BI28: =BA28+BD28+BE28 -> 0 | BJ28: =BH28/BH$55 -> #DIV/0! | BK28: =BI28/BI$55 -> #DIV/0! | BN28: =BL28*BL$16+BM28*BM$16 -> 0 | BO28: =IF(BL28=0,0,BL28/BL$55) -> 0 | BP28: =BH28+BL28 -> 0 | BQ28: =BI28+BL28+BM28 -> 0 | BR28: =BP28/BP$55 -> #DIV/0! | BS28: =BQ28/BQ$55 -> #DIV/0! | BV28: =BT28*BT$16+BU28*BU$16 -> 0 | BW28: =IF(BT28=0,0,BT28/BT$55) -> 0 | BX28: =BP28+BT28 -> 0 | BY28: =BQ28+BT28+BU28 -> 0 | BZ28: =BX28/BX$55 -> #DIV/0! | CA28: =BY28/BY$55 -> #DIV/0! | CC28: =SUM(J28,R28,Z28,AH28,AP28,AX28,BF28,BN28,BV28) -> #DIV/0!
D29: Investor 9 | J29: =H29*H$16+I29*I$16 -> #DIV/0! | K29: =IF(H29=0,0,H29/H$55) -> 0 | L29: =$H29 -> 0 | M29: =IF(SUM($E29:$G29)+$H29+$I29=0,,SUM($E29:$G29)+$H29+$I29) -> 0 | N29: =L29/L$55 -> #DIV/0! | O29: =M29/M$55 -> #DIV/0! | R29: =P29*P$16+Q29*Q$16 -> 0 | S29: =IF(P29=0,0,P29/P$55) -> 0 | T29: =L29+P29 -> 0 | U29: =M29+P29+Q29 -> 0 | V29: =T29/T$55 -> #DIV/0! | W29: =U29/U$55 -> #DIV/0! | Z29: =X29*X$16+Y29*Y$16 -> 0 | AA29: =IF(X29=0,0,X29/X$55) -> 0 | AB29: =T29+X29 -> 0 | AC29: =U29+X29+Y29 -> 0 | AD29: =AB29/AB$55 -> #DIV/0! | AE29: =AC29/AC$55 -> #DIV/0! | AH29: =AF29*AF$16+AG29*AG$16 -> 0 | AI29: =IF(AF29=0,0,AF29/AF$55) -> 0 | AJ29: =AB29+AF29 -> 0 | AK29: =AC29+AF29+AG29 -> 0 | AL29: =AJ29/AJ$55 -> #DIV/0! | AM29: =AK29/AK$55 -> #DIV/0! | AP29: =AN29*AN$16+AO29*AO$16 -> 0 | AQ29: =IF(AN29=0,0,AN29/AN$55) -> 0 | AR29: =AJ29+AN29 -> 0 | AS29: =AK29+AN29+AO29 -> 0 | AT29: =AR29/AR$55 -> #DIV/0! | AU29: =AS29/AS$55 -> #DIV/0! | AX29: =AV29*AV$16+AW29*AW$16 -> 0 | AY29: =IF(AV29=0,0,AV29/AV$55) -> 0 | AZ29: =AR29+AV29 -> 0 | BA29: =AS29+AV29+AW29 -> 0 | BB29: =AZ29/AZ$55 -> #DIV/0! | BC29: =BA29/BA$55 -> #DIV/0! | BF29: =BD29*BD$16+BE29*BE$16 -> 0 | BG29: =IF(BD29=0,0,BD29/BD$55) -> 0 | BH29: =AZ29+BD29 -> 0 | BI29: =BA29+BD29+BE29 -> 0 | BJ29: =BH29/BH$55 -> #DIV/0! | BK29: =BI29/BI$55 -> #DIV/0! | BN29: =BL29*BL$16+BM29*BM$16 -> 0 | BO29: =IF(BL29=0,0,BL29/BL$55) -> 0 | BP29: =BH29+BL29 -> 0 | BQ29: =BI29+BL29+BM29 -> 0 | BR29: =BP29/BP$55 -> #DIV/0! | BS29: =BQ29/BQ$55 -> #DIV/0! | BV29: =BT29*BT$16+BU29*BU$16 -> 0 | BW29: =IF(BT29=0,0,BT29/BT$55) -> 0 | BX29: =BP29+BT29 -> 0 | BY29: =BQ29+BT29+BU29 -> 0 | BZ29: =BX29/BX$55 -> #DIV/0! | CA29: =BY29/BY$55 -> #DIV/0! | CC29: =SUM(J29,R29,Z29,AH29,AP29,AX29,BF29,BN29,BV29) -> #DIV/0!
D30: Investor 10 | J30: =H30*H$16+I30*I$16 -> #DIV/0! | K30: =IF(H30=0,0,H30/H$55) -> 0 | L30: =$H30 -> 0 | M30: =IF(SUM($E30:$G30)+$H30+$I30=0,,SUM($E30:$G30)+$H30+$I30) -> 0 | N30: =L30/L$55 -> #DIV/0! | O30: =M30/M$55 -> #DIV/0! | R30: =P30*P$16+Q30*Q$16 -> 0 | S30: =IF(P30=0,0,P30/P$55) -> 0 | T30: =L30+P30 -> 0 | U30: =M30+P30+Q30 -> 0 | V30: =T30/T$55 -> #DIV/0! | W30: =U30/U$55 -> #DIV/0! | Z30: =X30*X$16+Y30*Y$16 -> 0 | AA30: =IF(X30=0,0,X30/X$55) -> 0 | AB30: =T30+X30 -> 0 | AC30: =U30+X30+Y30 -> 0 | AD30: =AB30/AB$55 -> #DIV/0! | AE30: =AC30/AC$55 -> #DIV/0! | AH30: =AF30*AF$16+AG30*AG$16 -> 0 | AI30: =IF(AF30=0,0,AF30/AF$55) -> 0 | AJ30: =AB30+AF30 -> 0 | AK30: =AC30+AF30+AG30 -> 0 | AL30: =AJ30/AJ$55 -> #DIV/0! | AM30: =AK30/AK$55 -> #DIV/0! | AP30: =AN30*AN$16+AO30*AO$16 -> 0 | AQ30: =IF(AN30=0,0,AN30/AN$55) -> 0 | AR30: =AJ30+AN30 -> 0 | AS30: =AK30+AN30+AO30 -> 0 | AT30: =AR30/AR$55 -> #DIV/0! | AU30: =AS30/AS$55 -> #DIV/0! | AX30: =AV30*AV$16+AW30*AW$16 -> 0 | AY30: =IF(AV30=0,0,AV30/AV$55) -> 0 | AZ30: =AR30+AV30 -> 0 | BA30: =AS30+AV30+AW30 -> 0 | BB30: =AZ30/AZ$55 -> #DIV/0! | BC30: =BA30/BA$55 -> #DIV/0! | BF30: =BD30*BD$16+BE30*BE$16 -> 0 | BG30: =IF(BD30=0,0,BD30/BD$55) -> 0 | BH30: =AZ30+BD30 -> 0 | BI30: =BA30+BD30+BE30 -> 0 | BJ30: =BH30/BH$55 -> #DIV/0! | BK30: =BI30/BI$55 -> #DIV/0! | BN30: =BL30*BL$16+BM30*BM$16 -> 0 | BO30: =IF(BL30=0,0,BL30/BL$55) -> 0 | BP30: =BH30+BL30 -> 0 | BQ30: =BI30+BL30+BM30 -> 0 | BR30: =BP30/BP$55 -> #DIV/0! | BS30: =BQ30/BQ$55 -> #DIV/0! | BV30: =BT30*BT$16+BU30*BU$16 -> 0 | BW30: =IF(BT30=0,0,BT30/BT$55) -> 0 | BX30: =BP30+BT30 -> 0 | BY30: =BQ30+BT30+BU30 -> 0 | BZ30: =BX30/BX$55 -> #DIV/0! | CA30: =BY30/BY$55 -> #DIV/0! | CC30: =SUM(J30,R30,Z30,AH30,AP30,AX30,BF30,BN30,BV30) -> #DIV/0!
D31: Investor 11 | J31: =H31*H$16+I31*I$16 -> #DIV/0! | K31: =IF(H31=0,0,H31/H$55) -> 0 | L31: =$H31 -> 0 | M31: =IF(SUM($E31:$G31)+$H31+$I31=0,,SUM($E31:$G31)+$H31+$I31) -> 0 | N31: =L31/L$55 -> #DIV/0! | O31: =M31/M$55 -> #DIV/0! | R31: =P31*P$16+Q31*Q$16 -> 0 | S31: =IF(P31=0,0,P31/P$55) -> 0 | T31: =L31+P31 -> 0 | U31: =M31+P31+Q31 -> 0 | V31: =T31/T$55 -> #DIV/0! | W31: =U31/U$55 -> #DIV/0! | Z31: =X31*X$16+Y31*Y$16 -> 0 | AA31: =IF(X31=0,0,X31/X$55) -> 0 | AB31: =T31+X31 -> 0 | AC31: =U31+X31+Y31 -> 0 | AD31: =AB31/AB$55 -> #DIV/0! | AE31: =AC31/AC$55 -> #DIV/0! | AH31: =AF31*AF$16+AG31*AG$16 -> 0 | AI31: =IF(AF31=0,0,AF31/AF$55) -> 0 | AJ31: =AB31+AF31 -> 0 | AK31: =AC31+AF31+AG31 -> 0 | AL31: =AJ31/AJ$55 -> #DIV/0! | AM31: =AK31/AK$55 -> #DIV/0! | AP31: =AN31*AN$16+AO31*AO$16 -> 0 | AQ31: =IF(AN31=0,0,AN31/AN$55) -> 0 | AR31: =AJ31+AN31 -> 0 | AS31: =AK31+AN31+AO31 -> 0 | AT31: =AR31/AR$55 -> #DIV/0! | AU31: =AS31/AS$55 -> #DIV/0! | AX31: =AV31*AV$16+AW31*AW$16 -> 0 | AY31: =IF(AV31=0,0,AV31/AV$55) -> 0 | AZ31: =AR31+AV31 -> 0 | BA31: =AS31+AV31+AW31 -> 0 | BB31: =AZ31/AZ$55 -> #DIV/0! | BC31: =BA31/BA$55 -> #DIV/0! | BF31: =BD31*BD$16+BE31*BE$16 -> 0 | BG31: =IF(BD31=0,0,BD31/BD$55) -> 0 | BH31: =AZ31+BD31 -> 0 | BI31: =BA31+BD31+BE31 -> 0 | BJ31: =BH31/BH$55 -> #DIV/0! | BK31: =BI31/BI$55 -> #DIV/0! | BN31: =BL31*BL$16+BM31*BM$16 -> 0 | BO31: =IF(BL31=0,0,BL31/BL$55) -> 0 | BP31: =BH31+BL31 -> 0 | BQ31: =BI31+BL31+BM31 -> 0 | BR31: =BP31/BP$55 -> #DIV/0! | BS31: =BQ31/BQ$55 -> #DIV/0! | BV31: =BT31*BT$16+BU31*BU$16 -> 0 | BW31: =IF(BT31=0,0,BT31/BT$55) -> 0 | BX31: =BP31+BT31 -> 0 | BY31: =BQ31+BT31+BU31 -> 0 | BZ31: =BX31/BX$55 -> #DIV/0! | CA31: =BY31/BY$55 -> #DIV/0! | CC31: =SUM(J31,R31,Z31,AH31,AP31,AX31,BF31,BN31,BV31) -> #DIV/0!
D32: Investor 12 | J32: =H32*H$16+I32*I$16 -> #DIV/0! | K32: =IF(H32=0,0,H32/H$55) -> 0 | L32: =$H32 -> 0 | M32: =IF(SUM($E32:$G32)+$H32+$I32=0,,SUM($E32:$G32)+$H32+$I32) -> 0 | N32: =L32/L$55 -> #DIV/0! | O32: =M32/M$55 -> #DIV/0! | R32: =P32*P$16+Q32*Q$16 -> 0 | S32: =IF(P32=0,0,P32/P$55) -> 0 | T32: =L32+P32 -> 0 | U32: =M32+P32+Q32 -> 0 | V32: =T32/T$55 -> #DIV/0! | W32: =U32/U$55 -> #DIV/0! | Z32: =X32*X$16+Y32*Y$16 -> 0 | AA32: =IF(X32=0,0,X32/X$55) -> 0 | AB32: =T32+X32 -> 0 | AC32: =U32+X32+Y32 -> 0 | AD32: =AB32/AB$55 -> #DIV/0! | AE32: =AC32/AC$55 -> #DIV/0! | AH32: =AF32*AF$16+AG32*AG$16 -> 0 | AI32: =IF(AF32=0,0,AF32/AF$55) -> 0 | AJ32: =AB32+AF32 -> 0 | AK32: =AC32+AF32+AG32 -> 0 | AL32: =AJ32/AJ$55 -> #DIV/0! | AM32: =AK32/AK$55 -> #DIV/0! | AP32: =AN32*AN$16+AO32*AO$16 -> 0 | AQ32: =IF(AN32=0,0,AN32/AN$55) -> 0 | AR32: =AJ32+AN32 -> 0 | AS32: =AK32+AN32+AO32 -> 0 | AT32: =AR32/AR$55 -> #DIV/0! | AU32: =AS32/AS$55 -> #DIV/0! | AX32: =AV32*AV$16+AW32*AW$16 -> 0 | AY32: =IF(AV32=0,0,AV32/AV$55) -> 0 | AZ32: =AR32+AV32 -> 0 | BA32: =AS32+AV32+AW32 -> 0 | BB32: =AZ32/AZ$55 -> #DIV/0! | BC32: =BA32/BA$55 -> #DIV/0! | BF32: =BD32*BD$16+BE32*BE$16 -> 0 | BG32: =IF(BD32=0,0,BD32/BD$55) -> 0 | BH32: =AZ32+BD32 -> 0 | BI32: =BA32+BD32+BE32 -> 0 | BJ32: =BH32/BH$55 -> #DIV/0! | BK32: =BI32/BI$55 -> #DIV/0! | BN32: =BL32*BL$16+BM32*BM$16 -> 0 | BO32: =IF(BL32=0,0,BL32/BL$55) -> 0 | BP32: =BH32+BL32 -> 0 | BQ32: =BI32+BL32+BM32 -> 0 | BR32: =BP32/BP$55 -> #DIV/0! | BS32: =BQ32/BQ$55 -> #DIV/0! | BV32: =BT32*BT$16+BU32*BU$16 -> 0 | BW32: =IF(BT32=0,0,BT32/BT$55) -> 0 | BX32: =BP32+BT32 -> 0 | BY32: =BQ32+BT32+BU32 -> 0 | BZ32: =BX32/BX$55 -> #DIV/0! | CA32: =BY32/BY$55 -> #DIV/0! | CC32: =SUM(J32,R32,Z32,AH32,AP32,AX32,BF32,BN32,BV32) -> #DIV/0!
... D41: Investor 6 | J41: =H41*H$16+I41*I$16 -> #DIV/0! | K41: =IF(H41=0,0,H41/H$55) -> 0 | L41: =$H41 -> 0 | M41: =IF(SUM($E41:$G41)+$H41+$I41=0,,SUM($E41:$G41)+$H41+$I41) -> 0 | N41: =L41/L$55 -> #DIV/0! | O41: =M41/M$55 -> #DIV/0! | R41: =P41*P$16+Q41*Q$16 -> 0 | S41: =IF(P41=0,0,P41/P$55) -> 0 | T41: =L41+P41 -> 0 | U41: =M41+P41+Q41 -> 0 | V41: =T41/T$55 -> #DIV/0! | W41: =U41/U$55 -> #DIV/0! | Z41: =X41*X$16+Y41*Y$16 -> 0 | AA41: =IF(X41=0,0,X41/X$55) -> 0 | AB41: =T41+X41 -> 0 | AC41: =U41+X41+Y41 -> 0 | AD41: =AB41/AB$55 -> #DIV/0! | AE41: =AC41/AC$55 -> #DIV/0! | AH41: =AF41*AF$16+AG41*AG$16 -> 0 | AI41: =IF(AF41=0,0,AF41/AF$55) -> 0 | AJ41: =AB41+AF41 -> 0 | AK41: =AC41+AF41+AG41 -> 0 | AL41: =AJ41/AJ$55 -> #DIV/0! | AM41: =AK41/AK$55 -> #DIV/0! | AP41: =AN41*AN$16+AO41*AO$16 -> 0 | AQ41: =IF(AN41=0,0,AN41/AN$55) -> 0 | AR41: =AJ41+AN41 -> 0 | AS41: =AK41+AN41+AO41 -> 0 | AT41: =AR41/AR$55 -> #DIV/0! | AU41: =AS41/AS$55 -> #DIV/0! | AX41: =AV41*AV$16+AW41*AW$16 -> 0 | AY41: =IF(AV41=0,0,AV41/AV$55) -> 0 | AZ41: =AR41+AV41 -> 0 | BA41: =AS41+AV41+AW41 -> 0 | BB41: =AZ41/AZ$55 -> #DIV/0! | BC41: =BA41/BA$55 -> #DIV/0! | BF41: =BD41*BD$16+BE41*BE$16 -> 0 | BG41: =IF(BD41=0,0,BD41/BD$55) -> 0 | BH41: =AZ41+BD41 -> 0 | BI41: =BA41+BD41+BE41 -> 0 | BJ41: =BH41/BH$55 -> #DIV/0! | BK41: =BI41/BI$55 -> #DIV/0! | BN41: =BL41*BL$16+BM41*BM$16 -> 0 | BO41: =IF(BL41=0,0,BL41/BL$55) -> 0 | BP41: =BH41+BL41 -> 0 | BQ41: =BI41+BL41+BM41 -> 0 | BR41: =BP41/BP$55 -> #DIV/0! | BS41: =BQ41/BQ$55 -> #DIV/0! | BV41: =BT41*BT$16+BU41*BU$16 -> 0 | BW41: =IF(BT41=0,0,BT41/BT$55) -> 0 | BX41: =BP41+BT41 -> 0 | BY41: =BQ41+BT41+BU41 -> 0 | BZ41: =BX41/BX$55 -> #DIV/0! | CA41: =BY41/BY$55 -> #DIV/0! | CC41: =SUM(J41,R41,Z41,AH41,AP41,AX41,BF41,BN41,BV41) -> #DIV/0!
J42: =H42*H$16+I42*I$16 -> #DIV/0! | K42: =IF(H42=0,0,H42/H$55) -> 0 | L42: =$H42 -> 0 | M42: =IF(SUM($E42:$G42)+$H42+$I42=0,,SUM($E42:$G42)+$H42+$I42) -> 0 | N42: =L42/L$55 -> #DIV/0! | O42: =M42/M$55 -> #DIV/0! | R42: =P42*P$16+Q42*Q$16 -> 0 | S42: =IF(P42=0,0,P42/P$55) -> 0 | T42: =L42+P42 -> 0 | U42: =M42+P42+Q42 -> 0 | V42: =T42/T$55 -> #DIV/0! | W42: =U42/U$55 -> #DIV/0! | Z42: =X42*X$16+Y42*Y$16 -> 0 | AA42: =IF(X42=0,0,X42/X$55) -> 0 | AB42: =T42+X42 -> 0 | AC42: =U42+X42+Y42 -> 0 | AD42: =AB42/AB$55 -> #DIV/0! | AE42: =AC42/AC$55 -> #DIV/0! | AH42: =AF42*AF$16+AG42*AG$16 -> 0 | AI42: =IF(AF42=0,0,AF42/AF$55) -> 0 | AJ42: =AB42+AF42 -> 0 | AK42: =AC42+AF42+AG42 -> 0 | AL42: =AJ42/AJ$55 -> #DIV/0! | AM42: =AK42/AK$55 -> #DIV/0! | AP42: =AN42*AN$16+AO42*AO$16 -> 0 | AQ42: =IF(AN42=0,0,AN42/AN$55) -> 0 | AR42: =AJ42+AN42 -> 0 | AS42: =AK42+AN42+AO42 -> 0 | AT42: =AR42/AR$55 -> #DIV/0! | AU42: =AS42/AS$55 -> #DIV/0! | AX42: =AV42*AV$16+AW42*AW$16 -> 0 | AY42: =IF(AV42=0,0,AV42/AV$55) -> 0 | AZ42: =AR42+AV42 -> 0 | BA42: =AS42+AV42+AW42 -> 0 | BB42: =AZ42/AZ$55 -> #DIV/0! | BC42: =BA42/BA$55 -> #DIV/0! | BF42: =BD42*BD$16+BE42*BE$16 -> 0 | BG42: =IF(BD42=0,0,BD42/BD$55) -> 0 | BH42: =AZ42+BD42 -> 0 | BI42: =BA42+BD42+BE42 -> 0 | BJ42: =BH42/BH$55 -> #DIV/0! | BK42: =BI42/BI$55 -> #DIV/0! | BN42: =BL42*BL$16+BM42*BM$16 -> 0 | BO42: =IF(BL42=0,0,BL42/BL$55) -> 0 | BP42: =BH42+BL42 -> 0 | BQ42: =BI42+BL42+BM42 -> 0 | BR42: =BP42/BP$55 -> #DIV/0! | BS42: =BQ42/BQ$55 -> #DIV/0! | BV42: =BT42*BT$16+BU42*BU$16 -> 0 | BW42: =IF(BT42=0,0,BT42/BT$55) -> 0 | BX42: =BP42+BT42 -> 0 | BY42: =BQ42+BT42+BU42 -> 0 | BZ42: =BX42/BX$55 -> #DIV/0! | CA42: =BY42/BY$55 -> #DIV/0! | CC42: =SUM(J42,R42,Z42,AH42,AP42,AX42,BF42,BN42,BV42) -> #DIV/0!
D43: Founders/Leadership | J43: =H43*H$16+I43*I$16 -> #DIV/0! | K43: =IF(H43=0,0,H43/H$55) -> 0 | L43: =$H43 -> 0 | M43: =IF(SUM($E43:$G43)+$H43+$I43=0,,SUM($E43:$G43)+$H43+$I43) -> 0 | N43: =L43/L$55 -> #DIV/0! | O43: =M43/M$55 -> #DIV/0! | R43: =P43*P$16+Q43*Q$16 -> 0 | S43: =IF(P43=0,0,P43/P$55) -> 0 | T43: =L43+P43 -> 0 | U43: =M43+P43+Q43 -> 0 | V43: =T43/T$55 -> #DIV/0! | W43: =U43/U$55 -> #DIV/0! | Z43: =X43*X$16+Y43*Y$16 -> 0 | AA43: =IF(X43=0,0,X43/X$55) -> 0 | AB43: =T43+X43 -> 0 | AC43: =U43+X43+Y43 -> 0 | AD43: =AB43/AB$55 -> #DIV/0! | AE43: =AC43/AC$55 -> #DIV/0! | AH43: =AF43*AF$16+AG43*AG$16 -> 0 | AI43: =IF(AF43=0,0,AF43/AF$55) -> 0 | AJ43: =AB43+AF43 -> 0 | AK43: =AC43+AF43+AG43 -> 0 | AL43: =AJ43/AJ$55 -> #DIV/0! | AM43: =AK43/AK$55 -> #DIV/0! | AP43: =AN43*AN$16+AO43*AO$16 -> 0 | AQ43: =IF(AN43=0,0,AN43/AN$55) -> 0 | AR43: =AJ43+AN43 -> 0 | AS43: =AK43+AN43+AO43 -> 0 | AT43: =AR43/AR$55 -> #DIV/0! | AU43: =AS43/AS$55 -> #DIV/0! | AX43: =AV43*AV$16+AW43*AW$16 -> 0 | AY43: =IF(AV43=0,0,AV43/AV$55) -> 0 | AZ43: =AR43+AV43 -> 0 | BA43: =AS43+AV43+AW43 -> 0 | BB43: =AZ43/AZ$55 -> #DIV/0! | BC43: =BA43/BA$55 -> #DIV/0! | BF43: =BD43*BD$16+BE43*BE$16 -> 0 | BG43: =IF(BD43=0,0,BD43/BD$55) -> 0 | BH43: =AZ43+BD43 -> 0 | BI43: =BA43+BD43+BE43 -> 0 | BJ43: =BH43/BH$55 -> #DIV/0! | BK43: =BI43/BI$55 -> #DIV/0! | BN43: =BL43*BL$16+BM43*BM$16 -> 0 | BO43: =IF(BL43=0,0,BL43/BL$55) -> 0 | BP43: =BH43+BL43 -> 0 | BQ43: =BI43+BL43+BM43 -> 0 | BR43: =BP43/BP$55 -> #DIV/0! | BS43: =BQ43/BQ$55 -> #DIV/0! | BV43: =BT43*BT$16+BU43*BU$16 -> 0 | BW43: =IF(BT43=0,0,BT43/BT$55) -> 0 | BX43: =BP43+BT43 -> 0 | BY43: =BQ43+BT43+BU43 -> 0 | BZ43: =BX43/BX$55 -> #DIV/0! | CA43: =BY43/BY$55 -> #DIV/0! | CC43: =SUM(J43,R43,Z43,AH43,AP43,AX43,BF43,BN43,BV43) -> #DIV/0!
D44: Others 1 | J44: =H44*H$16+I44*I$16 -> #DIV/0! | K44: =IF(H44=0,0,H44/H$55) -> 0 | L44: =$H44 -> 0 | M44: =IF(SUM($E44:$G44)+$H44+$I44=0,,SUM($E44:$G44)+$H44+$I44) -> 0 | N44: =L44/L$55 -> #DIV/0! | O44: =M44/M$55 -> #DIV/0! | R44: =P44*P$16+Q44*Q$16 -> 0 | S44: =IF(P44=0,0,P44/P$55) -> 0 | T44: =L44+P44 -> 0 | U44: =M44+P44+Q44 -> 0 | V44: =T44/T$55 -> #DIV/0! | W44: =U44/U$55 -> #DIV/0! | Z44: =X44*X$16+Y44*Y$16 -> 0 | AA44: =IF(X44=0,0,X44/X$55) -> 0 | AB44: =T44+X44 -> 0 | AC44: =U44+X44+Y44 -> 0 | AD44: =AB44/AB$55 -> #DIV/0! | AE44: =AC44/AC$55 -> #DIV/0! | AH44: =AF44*AF$16+AG44*AG$16 -> 0 | AI44: =IF(AF44=0,0,AF44/AF$55) -> 0 | AJ44: =AB44+AF44 -> 0 | AK44: =AC44+AF44+AG44 -> 0 | AL44: =AJ44/AJ$55 -> #DIV/0! | AM44: =AK44/AK$55 -> #DIV/0! | AP44: =AN44*AN$16+AO44*AO$16 -> 0 | AQ44: =IF(AN44=0,0,AN44/AN$55) -> 0 | AR44: =AJ44+AN44 -> 0 | AS44: =AK44+AN44+AO44 -> 0 | AT44: =AR44/AR$55 -> #DIV/0! | AU44: =AS44/AS$55 -> #DIV/0! | AX44: =AV44*AV$16+AW44*AW$16 -> 0 | AY44: =IF(AV44=0,0,AV44/AV$55) -> 0 | AZ44: =AR44+AV44 -> 0 | BA44: =AS44+AV44+AW44 -> 0 | BB44: =AZ44/AZ$55 -> #DIV/0! | BC44: =BA44/BA$55 -> #DIV/0! | BF44: =BD44*BD$16+BE44*BE$16 -> 0 | BG44: =IF(BD44=0,0,BD44/BD$55) -> 0 | BH44: =AZ44+BD44 -> 0 | BI44: =BA44+BD44+BE44 -> 0 | BJ44: =BH44/BH$55 -> #DIV/0! | BK44: =BI44/BI$55 -> #DIV/0! | BN44: =BL44*BL$16+BM44*BM$16 -> 0 | BO44: =IF(BL44=0,0,BL44/BL$55) -> 0 | BP44: =BH44+BL44 -> 0 | BQ44: =BI44+BL44+BM44 -> 0 | BR44: =BP44/BP$55 -> #DIV/0! | BS44: =BQ44/BQ$55 -> #DIV/0! | BV44: =BT44*BT$16+BU44*BU$16 -> 0 | BW44: =IF(BT44=0,0,BT44/BT$55) -> 0 | BX44: =BP44+BT44 -> 0 | BY44: =BQ44+BT44+BU44 -> 0 | BZ44: =BX44/BX$55 -> #DIV/0! | CA44: =BY44/BY$55 -> #DIV/0! | CC44: =SUM(J44,R44,Z44,AH44,AP44,AX44,BF44,BN44,BV44) -> #DIV/0!
D45: Others 2 | J45: =H45*H$16+I45*I$16 -> #DIV/0! | K45: =IF(H45=0,0,H45/H$55) -> 0 | L45: =$H45 -> 0 | M45: =IF(SUM($E45:$G45)+$H45+$I45=0,,SUM($E45:$G45)+$H45+$I45) -> 0 | N45: =L45/L$55 -> #DIV/0! | O45: =M45/M$55 -> #DIV/0! | R45: =P45*P$16+Q45*Q$16 -> 0 | S45: =IF(P45=0,0,P45/P$55) -> 0 | T45: =L45+P45 -> 0 | U45: =M45+P45+Q45 -> 0 | V45: =T45/T$55 -> #DIV/0! | W45: =U45/U$55 -> #DIV/0! | Z45: =X45*X$16+Y45*Y$16 -> 0 | AA45: =IF(X45=0,0,X45/X$55) -> 0 | AB45: =T45+X45 -> 0 | AC45: =U45+X45+Y45 -> 0 | AD45: =AB45/AB$55 -> #DIV/0! | AE45: =AC45/AC$55 -> #DIV/0! | AH45: =AF45*AF$16+AG45*AG$16 -> 0 | AI45: =IF(AF45=0,0,AF45/AF$55) -> 0 | AJ45: =AB45+AF45 -> 0 | AK45: =AC45+AF45+AG45 -> 0 | AL45: =AJ45/AJ$55 -> #DIV/0! | AM45: =AK45/AK$55 -> #DIV/0! | AP45: =AN45*AN$16+AO45*AO$16 -> 0 | AQ45: =IF(AN45=0,0,AN45/AN$55) -> 0 | AR45: =AJ45+AN45 -> 0 | AS45: =AK45+AN45+AO45 -> 0 | AT45: =AR45/AR$55 -> #DIV/0! | AU45: =AS45/AS$55 -> #DIV/0! | AX45: =AV45*AV$16+AW45*AW$16 -> 0 | AY45: =IF(AV45=0,0,AV45/AV$55) -> 0 | AZ45: =AR45+AV45 -> 0 | BA45: =AS45+AV45+AW45 -> 0 | BB45: =AZ45/AZ$55 -> #DIV/0! | BC45: =BA45/BA$55 -> #DIV/0! | BF45: =BD45*BD$16+BE45*BE$16 -> 0 | BG45: =IF(BD45=0,0,BD45/BD$55) -> 0 | BH45: =AZ45+BD45 -> 0 | BI45: =BA45+BD45+BE45 -> 0 | BJ45: =BH45/BH$55 -> #DIV/0! | BK45: =BI45/BI$55 -> #DIV/0! | BN45: =BL45*BL$16+BM45*BM$16 -> 0 | BO45: =IF(BL45=0,0,BL45/BL$55) -> 0 | BP45: =BH45+BL45 -> 0 | BQ45: =BI45+BL45+BM45 -> 0 | BR45: =BP45/BP$55 -> #DIV/0! | BS45: =BQ45/BQ$55 -> #DIV/0! | BV45: =BT45*BT$16+BU45*BU$16 -> 0 | BW45: =IF(BT45=0,0,BT45/BT$55) -> 0 | BX45: =BP45+BT45 -> 0 | BY45: =BQ45+BT45+BU45 -> 0 | BZ45: =BX45/BX$55 -> #DIV/0! | CA45: =BY45/BY$55 -> #DIV/0! | CC45: =SUM(J45,R45,Z45,AH45,AP45,AX45,BF45,BN45,BV45) -> #DIV/0!
D46: Others 3 | J46: =H46*H$16+I46*I$16 -> #DIV/0! | K46: =IF(H46=0,0,H46/H$55) -> 0 | L46: =$H46 -> 0 | M46: =IF(SUM($E46:$G46)+$H46+$I46=0,,SUM($E46:$G46)+$H46+$I46) -> 0 | N46: =L46/L$55 -> #DIV/0! | O46: =M46/M$55 -> #DIV/0! | R46: =P46*P$16+Q46*Q$16 -> 0 | S46: =IF(P46=0,0,P46/P$55) -> 0 | T46: =L46+P46 -> 0 | U46: =M46+P46+Q46 -> 0 | V46: =T46/T$55 -> #DIV/0! | W46: =U46/U$55 -> #DIV/0! | Z46: =X46*X$16+Y46*Y$16 -> 0 | AA46: =IF(X46=0,0,X46/X$55) -> 0 | AB46: =T46+X46 -> 0 | AC46: =U46+X46+Y46 -> 0 | AD46: =AB46/AB$55 -> #DIV/0! | AE46: =AC46/AC$55 -> #DIV/0! | AH46: =AF46*AF$16+AG46*AG$16 -> 0 | AI46: =IF(AF46=0,0,AF46/AF$55) -> 0 | AJ46: =AB46+AF46 -> 0 | AK46: =AC46+AF46+AG46 -> 0 | AL46: =AJ46/AJ$55 -> #DIV/0! | AM46: =AK46/AK$55 -> #DIV/0! | AP46: =AN46*AN$16+AO46*AO$16 -> 0 | AQ46: =IF(AN46=0,0,AN46/AN$55) -> 0 | AR46: =AJ46+AN46 -> 0 | AS46: =AK46+AN46+AO46 -> 0 | AT46: =AR46/AR$55 -> #DIV/0! | AU46: =AS46/AS$55 -> #DIV/0! | AX46: =AV46*AV$16+AW46*AW$16 -> 0 | AY46: =IF(AV46=0,0,AV46/AV$55) -> 0 | AZ46: =AR46+AV46 -> 0 | BA46: =AS46+AV46+AW46 -> 0 | BB46: =AZ46/AZ$55 -> #DIV/0! | BC46: =BA46/BA$55 -> #DIV/0! | BF46: =BD46*BD$16+BE46*BE$16 -> 0 | BG46: =IF(BD46=0,0,BD46/BD$55) -> 0 | BH46: =AZ46+BD46 -> 0 | BI46: =BA46+BD46+BE46 -> 0 | BJ46: =BH46/BH$55 -> #DIV/0! | BK46: =BI46/BI$55 -> #DIV/0! | BN46: =BL46*BL$16+BM46*BM$16 -> 0 | BO46: =IF(BL46=0,0,BL46/BL$55) -> 0 | BP46: =BH46+BL46 -> 0 | BQ46: =BI46+BL46+BM46 -> 0 | BR46: =BP46/BP$55 -> #DIV/0! | BS46: =BQ46/BQ$55 -> #DIV/0! | BV46: =BT46*BT$16+BU46*BU$16 -> 0 | BW46: =IF(BT46=0,0,BT46/BT$55) -> 0 | BX46: =BP46+BT46 -> 0 | BY46: =BQ46+BT46+BU46 -> 0 | BZ46: =BX46/BX$55 -> #DIV/0! | CA46: =BY46/BY$55 -> #DIV/0! | CC46: =SUM(J46,R46,Z46,AH46,AP46,AX46,BF46,BN46,BV46) -> #DIV/0!
D47: Others 4 | J47: =H47*H$16+I47*I$16 -> #DIV/0! | K47: =IF(H47=0,0,H47/H$55) -> 0 | L47: =$H47 -> 0 | M47: =IF(SUM($E47:$G47)+$H47+$I47=0,,SUM($E47:$G47)+$H47+$I47) -> 0 | N47: =L47/L$55 -> #DIV/0! | O47: =M47/M$55 -> #DIV/0! | R47: =P47*P$16+Q47*Q$16 -> 0 | S47: =IF(P47=0,0,P47/P$55) -> 0 | T47: =L47+P47 -> 0 | U47: =M47+P47+Q47 -> 0 | V47: =T47/T$55 -> #DIV/0! | W47: =U47/U$55 -> #DIV/0! | Z47: =X47*X$16+Y47*Y$16 -> 0 | AA47: =IF(X47=0,0,X47/X$55) -> 0 | AB47: =T47+X47 -> 0 | AC47: =U47+X47+Y47 -> 0 | AD47: =AB47/AB$55 -> #DIV/0! | AE47: =AC47/AC$55 -> #DIV/0! | AH47: =AF47*AF$16+AG47*AG$16 -> 0 | AI47: =IF(AF47=0,0,AF47/AF$55) -> 0 | AJ47: =AB47+AF47 -> 0 | AK47: =AC47+AF47+AG47 -> 0 | AL47: =AJ47/AJ$55 -> #DIV/0! | AM47: =AK47/AK$55 -> #DIV/0! | AP47: =AN47*AN$16+AO47*AO$16 -> 0 | AQ47: =IF(AN47=0,0,AN47/AN$55) -> 0 | AR47: =AJ47+AN47 -> 0 | AS47: =AK47+AN47+AO47 -> 0 | AT47: =AR47/AR$55 -> #DIV/0! | AU47: =AS47/AS$55 -> #DIV/0! | AX47: =AV47*AV$16+AW47*AW$16 -> 0 | AY47: =IF(AV47=0,0,AV47/AV$55) -> 0 | AZ47: =AR47+AV47 -> 0 | BA47: =AS47+AV47+AW47 -> 0 | BB47: =AZ47/AZ$55 -> #DIV/0! | BC47: =BA47/BA$55 -> #DIV/0! | BF47: =BD47*BD$16+BE47*BE$16 -> 0 | BG47: =IF(BD47=0,0,BD47/BD$55) -> 0 | BH47: =AZ47+BD47 -> 0 | BI47: =BA47+BD47+BE47 -> 0 | BJ47: =BH47/BH$55 -> #DIV/0! | BK47: =BI47/BI$55 -> #DIV/0! | BN47: =BL47*BL$16+BM47*BM$16 -> 0 | BO47: =IF(BL47=0,0,BL47/BL$55) -> 0 | BP47: =BH47+BL47 -> 0 | BQ47: =BI47+BL47+BM47 -> 0 | BR47: =BP47/BP$55 -> #DIV/0! | BS47: =BQ47/BQ$55 -> #DIV/0! | BV47: =BT47*BT$16+BU47*BU$16 -> 0 | BW47: =IF(BT47=0,0,BT47/BT$55) -> 0 | BX47: =BP47+BT47 -> 0 | BY47: =BQ47+BT47+BU47 -> 0 | BZ47: =BX47/BX$55 -> #DIV/0! | CA47: =BY47/BY$55 -> #DIV/0! | CC47: =SUM(J47,R47,Z47,AH47,AP47,AX47,BF47,BN47,BV47) -> #DIV/0!
D48: Others 1 | J48: =H48*H$16+I48*I$16 -> #DIV/0! | K48: =IF(H48=0,0,H48/H$55) -> 0 | L48: =$H48 -> 0 | M48: =IF(SUM($E48:$G48)+$H48+$I48=0,,SUM($E48:$G48)+$H48+$I48) -> 0 | N48: =L48/L$55 -> #DIV/0! | O48: =M48/M$55 -> #DIV/0! | R48: =P48*P$16+Q48*Q$16 -> 0 | S48: =IF(P48=0,0,P48/P$55) -> 0 | T48: =L48+P48 -> 0 | U48: =M48+P48+Q48 -> 0 | V48: =T48/T$55 -> #DIV/0! | W48: =U48/U$55 -> #DIV/0! | Z48: =X48*X$16+Y48*Y$16 -> 0 | AA48: =IF(X48=0,0,X48/X$55) -> 0 | AB48: =T48+X48 -> 0 | AC48: =U48+X48+Y48 -> 0 | AD48: =AB48/AB$55 -> #DIV/0! | AE48: =AC48/AC$55 -> #DIV/0! | AH48: =AF48*AF$16+AG48*AG$16 -> 0 | AI48: =IF(AF48=0,0,AF48/AF$55) -> 0 | AJ48: =AB48+AF48 -> 0 | AK48: =AC48+AF48+AG48 -> 0 | AL48: =AJ48/AJ$55 -> #DIV/0! | AM48: =AK48/AK$55 -> #DIV/0! | AP48: =AN48*AN$16+AO48*AO$16 -> 0 | AQ48: =IF(AN48=0,0,AN48/AN$55) -> 0 | AR48: =AJ48+AN48 -> 0 | AS48: =AK48+AN48+AO48 -> 0 | AT48: =AR48/AR$55 -> #DIV/0! | AU48: =AS48/AS$55 -> #DIV/0! | AX48: =AV48*AV$16+AW48*AW$16 -> 0 | AY48: =IF(AV48=0,0,AV48/AV$55) -> 0 | AZ48: =AR48+AV48 -> 0 | BA48: =AS48+AV48+AW48 -> 0 | BB48: =AZ48/AZ$55 -> #DIV/0! | BC48: =BA48/BA$55 -> #DIV/0! | BF48: =BD48*BD$16+BE48*BE$16 -> 0 | BG48: =IF(BD48=0,0,BD48/BD$55) -> 0 | BH48: =AZ48+BD48 -> 0 | BI48: =BA48+BD48+BE48 -> 0 | BJ48: =BH48/BH$55 -> #DIV/0! | BK48: =BI48/BI$55 -> #DIV/0! | BN48: =BL48*BL$16+BM48*BM$16 -> 0 | BO48: =IF(BL48=0,0,BL48/BL$55) -> 0 | BP48: =BH48+BL48 -> 0 | BQ48: =BI48+BL48+BM48 -> 0 | BR48: =BP48/BP$55 -> #DIV/0! | BS48: =BQ48/BQ$55 -> #DIV/0! | BV48: =BT48*BT$16+BU48*BU$16 -> 0 | BW48: =IF(BT48=0,0,BT48/BT$55) -> 0 | BX48: =BP48+BT48 -> 0 | BY48: =BQ48+BT48+BU48 -> 0 | BZ48: =BX48/BX$55 -> #DIV/0! | CA48: =BY48/BY$55 -> #DIV/0! | CC48: =SUM(J48,R48,Z48,AH48,AP48,AX48,BF48,BN48,BV48) -> #DIV/0!
J49: =H49*H$16+I49*I$16 -> #DIV/0! | K49: =IF(H49=0,0,H49/H$55) -> 0 | L49: =$H49 -> 0 | M49: =IF(SUM($E49:$G49)+$H49+$I49=0,,SUM($E49:$G49)+$H49+$I49) -> 0 | N49: =L49/L$55 -> #DIV/0! | O49: =M49/M$55 -> #DIV/0! | R49: =P49*P$16+Q49*Q$16 -> 0 | S49: =IF(P49=0,0,P49/P$55) -> 0 | T49: =L49+P49 -> 0 | U49: =M49+P49+Q49 -> 0 | V49: =T49/T$55 -> #DIV/0! | W49: =U49/U$55 -> #DIV/0! | Z49: =X49*X$16+Y49*Y$16 -> 0 | AA49: =IF(X49=0,0,X49/X$55) -> 0 | AB49: =T49+X49 -> 0 | AC49: =U49+X49+Y49 -> 0 | AD49: =AB49/AB$55 -> #DIV/0! | AE49: =AC49/AC$55 -> #DIV/0! | AH49: =AF49*AF$16+AG49*AG$16 -> 0 | AI49: =IF(AF49=0,0,AF49/AF$55) -> 0 | AJ49: =AB49+AF49 -> 0 | AK49: =AC49+AF49+AG49 -> 0 | AL49: =AJ49/AJ$55 -> #DIV/0! | AM49: =AK49/AK$55 -> #DIV/0! | AP49: =AN49*AN$16+AO49*AO$16 -> 0 | AQ49: =IF(AN49=0,0,AN49/AN$55) -> 0 | AR49: =AJ49+AN49 -> 0 | AS49: =AK49+AN49+AO49 -> 0 | AT49: =AR49/AR$55 -> #DIV/0! | AU49: =AS49/AS$55 -> #DIV/0! | AX49: =AV49*AV$16+AW49*AW$16 -> 0 | AY49: =IF(AV49=0,0,AV49/AV$55) -> 0 | AZ49: =AR49+AV49 -> 0 | BA49: =AS49+AV49+AW49 -> 0 | BB49: =AZ49/AZ$55 -> #DIV/0! | BC49: =BA49/BA$55 -> #DIV/0! | BF49: =BD49*BD$16+BE49*BE$16 -> 0 | BG49: =IF(BD49=0,0,BD49/BD$55) -> 0 | BH49: =AZ49+BD49 -> 0 | BI49: =BA49+BD49+BE49 -> 0 | BJ49: =BH49/BH$55 -> #DIV/0! | BK49: =BI49/BI$55 -> #DIV/0! | BN49: =BL49*BL$16+BM49*BM$16 -> 0 | BO49: =IF(BL49=0,0,BL49/BL$55) -> 0 | BP49: =BH49+BL49 -> 0 | BQ49: =BI49+BL49+BM49 -> 0 | BR49: =BP49/BP$55 -> #DIV/0! | BS49: =BQ49/BQ$55 -> #DIV/0! | BV49: =BT49*BT$16+BU49*BU$16 -> 0 | BW49: =IF(BT49=0,0,BT49/BT$55) -> 0 | BX49: =BP49+BT49 -> 0 | BY49: =BQ49+BT49+BU49 -> 0 | BZ49: =BX49/BX$55 -> #DIV/0! | CA49: =BY49/BY$55 -> #DIV/0! | CC49: =SUM(J49,R49,Z49,AH49,AP49,AX49,BF49,BN49,BV49) -> #DIV/0!
D51: ESOP - allocated | M51: =IF(SUM($E51:$G51)=0,,SUM($E51:$G51)) -> 0 | O51: =M51/M$55 -> #DIV/0! | U51: =IF(M51=0,,M51) -> 0 | W51: =U51/U$55 -> #DIV/0! | AC51: =IF(U51=0,,U51) -> 0 | AE51: =AC51/AC$55 -> #DIV/0! | AK51: =IF(AC51=0,,AC51) -> 0 | AM51: =AK51/AK$55 -> #DIV/0! | AS51: =IF(AK51=0,,AK51) -> 0 | AU51: =AS51/AS$55 -> #DIV/0! | BA51: =IF(AS51=0,,AS51) -> 0 | BC51: =BA51/BA$55 -> #DIV/0! | BI51: =IF(BA51=0,,BA51) -> 0 | BK51: =BI51/BI$55 -> #DIV/0! | BQ51: =IF(BI51=0,,BI51) -> 0 | BS51: =BQ51/BQ$55 -> #DIV/0! | BY51: =IF(BQ51=0,,BQ51) -> 0 | CA51: =BY51/BY$55 -> #DIV/0!
...

Sheet Exit & Liquidation Analysis
A1: A.Brack
C2: ="Project " & 'Master Inputs'!$D$8 & " - Exit Analysis" -> Project MODEL - Exit Analysis
C3: Enter data in Yellow. Leave it blank if not relevant or not available. Optional data enter in Light Blue cells.
G4: DTC Cash Flow | O4: Round Summary
C5: Summary: | G5: Round | H5: Date | I5: DTC Investment | O5: Round | P5: Seniority | Q5: Liq. Multiple | R5: TT Invested | S5: DTC Investment
C6: Total Invested in Preferred Stocks | D6: ='Cap Table'!CC55/1000000 -> #DIV/0! | G6: ='Cap Table'!H$13 -> Seed | H6: =IF(ISNONTEXT('Cap Table'!H$14)=TRUE,'Cap Table'!H$14,0) -> 0 | I6: =-'Cap Table'!J$20/1000000 -> #DIV/0! | O6: ='Cap Table'!$H$13 -> Seed | P6: =IF(VLOOKUP(O6,$G$6:$I$14,2,FALSE)<>0,HLOOKUP(O6,'Cap Table'!$H$13:$CA$18,6,FALSE),) -> 0 | Q6: =IF(VLOOKUP(O6,$G$6:$I$14,2,FALSE)<>0,HLOOKUP(O6,'Cap Table'!$H$13:$CA$18,5,FALSE),) -> 0 | R6: =IF(VLOOKUP(O6,$G$6:$I$14,2,FALSE)<>0,-OFFSET('Cap Table'!$H$13,27,-6+MATCH(O6,'Cap Table'!$13:$13,0))/1000000,) -> 0 | S6: =VLOOKUP(O6,$G$6:$I$14,3,FALSE) -> #DIV/0!
C7: Total DTC Invested | D7: ='Cap Table'!CC20/1000000 -> #DIV/0! | G7: ='Cap Table'!P$13 -> Series A | H7: =IF(ISNONTEXT('Cap Table'!P$14)=TRUE,'Cap Table'!P$14,0) -> 0 | I7: =-'Cap Table'!R$20/1000000 -> 0 | O7: ='Cap Table'!$P$13 -> Series A | P7: =IF(VLOOKUP(O7,$G$6:$I$14,2,FALSE)<>0,HLOOKUP(O7,'Cap Table'!$H$13:$CA$18,6,FALSE),) -> 0 | Q7: =IF(VLOOKUP(O7,$G$6:$I$14,2,FALSE)<>0,HLOOKUP(O7,'Cap Table'!$H$13:$CA$18,5,FALSE),) -> 0 | R7: =IF(VLOOKUP(O7,$G$6:$I$14,2,FALSE)<>0,-OFFSET('Cap Table'!$H$13,27,-6+MATCH(O7,'Cap Table'!$13:$13,0))/1000000,) -> 0 | S7: =VLOOKUP(O7,$G$6:$I$14,3,FALSE) -> 0
C8: New Money DTC Invested
C9: Investors Liquidation preference - USD | D9: =D6 -> #DIV/0! | G9: ='Cap Table'!X$13 -> Series B | H9: =IF(ISNONTEXT('Cap Table'!X$14)=TRUE,'Cap Table'!X$14,0) -> 0 | I9: =-'Cap Table'!Z$20/1000000 -> 0 | O9: ='Cap Table'!$X$13 -> Series B | P9: =IF(VLOOKUP(O9,$G$6:$I$14,2,FALSE)<>0,HLOOKUP(O9,'Cap Table'!$H$13:$CA$18,6,FALSE),) -> 0 | Q9: =IF(VLOOKUP(O9,$G$6:$I$14,2,FALSE)<>0,HLOOKUP(O9,'Cap Table'!$H$13:$CA$18,5,FALSE),) -> 0 | R9: =IF(VLOOKUP(O9,$G$6:$I$14,2,FALSE)<>0,-OFFSET('Cap Table'!$H$13,27,-6+MATCH(O9,'Cap Table'!$13:$13,0))/1000000,) -> 0 | S9: =VLOOKUP(O9,$G$6:$I$14,3,FALSE) -> 0
C10: DTC Liquidation preference - USD | D10: =D7 -> #DIV/0! | G10: ='Cap Table'!AF$13 -> Series C | H10: =IF(ISNONTEXT('Cap Table'!AF$14)=TRUE,'Cap Table'!AF$14,0) -> 0 | I10: =-'Cap Table'!AH$20/1000000 -> 0 | O10: ='Cap Table'!$AF$13 -> Series C | P10: =IF(VLOOKUP(O10,$G$6:$I$14,2,FALSE)<>0,HLOOKUP(O10,'Cap Table'!$H$13:$CA$18,6,FALSE),) -> 0 | Q10: =IF(VLOOKUP(O10,$G$6:$I$14,2,FALSE)<>0,HLOOKUP(O10,'Cap Table'!$H$13:$CA$18,5,FALSE),) -> 0 | R10: =IF(VLOOKUP(O10,$G$6:$I$14,2,FALSE)<>0,-OFFSET('Cap Table'!$H$13,27,-6+MATCH(O10,'Cap Table'!$13:$13,0))/1000000,) -> 0 | S10: =VLOOKUP(O10,$G$6:$I$14,3,FALSE) -> 0
C11: Preferred Stocks DTC Ownership | D11: ='Cap Table'!BZ20 -> #DIV/0! | G11: ='Cap Table'!AN$13 -> Series D | H11: =IF(ISNONTEXT('Cap Table'!AN$14)=TRUE,'Cap Table'!AN$14,0) -> 0 | I11: =-'Cap Table'!AP$20/1000000 -> 0 | O11: ='Cap Table'!$AN$13 -> Series D | P11: =IF(VLOOKUP(O11,$G$6:$I$14,2,FALSE)<>0,HLOOKUP(O11,'Cap Table'!$H$13:$CA$18,6,FALSE),) -> 0 | Q11: =IF(VLOOKUP(O11,$G$6:$I$14,2,FALSE)<>0,HLOOKUP(O11,'Cap Table'!$H$13:$CA$18,5,FALSE),) -> 0 | R11: =IF(VLOOKUP(O11,$G$6:$I$14,2,FALSE)<>0,-OFFSET('Cap Table'!$H$13,27,-6+MATCH(O11,'Cap Table'!$13:$13,0))/1000000,) -> 0 | S11: =VLOOKUP(O11,$G$6:$I$14,3,FALSE) -> 0
C12: Fully Diluted DTC Ownership | D12: ='Cap Table'!CA20 -> #DIV/0! | G12: ='Cap Table'!AV$13 -> Series E | H12: =IF(ISNONTEXT('Cap Table'!AV$14)=TRUE,'Cap Table'!AV$14,0) -> 0 | I12: =-'Cap Table'!AX$20/1000000 -> 0 | O12: ='Cap Table'!$AV$13 -> Series E | P12: =IF(VLOOKUP(O12,$G$6:$I$14,2,FALSE)<>0,HLOOKUP(O12,'Cap Table'!$H$13:$CA$18,6,FALSE),) -> 0 | Q12: =IF(VLOOKUP(O12,$G$6:$I$14,2,FALSE)<>0,HLOOKUP(O12,'Cap Table'!$H$13:$CA$18,5,FALSE),) -> 0 | R12: =IF(VLOOKUP(O12,$G$6:$I$14,2,FALSE)<>0,-OFFSET('Cap Table'!$H$13,27,-6+MATCH(O12,'Cap Table'!$13:$13,0))/1000000,) -> 0 | S12: =VLOOKUP(O12,$G$6:$I$14,3,FALSE) -> 0
C13: New Money DTC Ownership | G13: ='Cap Table'!BD13 -> Series E-1 | H13: =IF(ISNONTEXT('Cap Table'!BD$14)=TRUE,'Cap Table'!BD$14,0) -> 0 | I13: =-'Cap Table'!BF20/1000000 -> 0 | O13: ='Cap Table'!$BD13 -> Series E-1 | P13: =IF(VLOOKUP(O13,$G$6:$I$14,2,FALSE)<>0,HLOOKUP(O13,'Cap Table'!$H$13:$CA$18,6,FALSE),) -> 0 | Q13: =IF(VLOOKUP(O13,$G$6:$I$14,2,FALSE)<>0,HLOOKUP(O13,'Cap Table'!$H$13:$CA$18,5,FALSE),) -> 0 | R13: =IF(VLOOKUP(O13,$G$6:$I$14,2,FALSE)<>0,-OFFSET('Cap Table'!$H$13,27,-6+MATCH(O13,'Cap Table'!$13:$13,0))/1000000,) -> 0 | S13: =VLOOKUP(O13,$G$6:$I$14,3,FALSE) -> 0
G14: ='Cap Table'!BT$13 -> Series G | H14: =IF(ISNONTEXT('Cap Table'!BT$14)=TRUE,'Cap Table'!BT$14,0) -> 0 | I14: =-'Cap Table'!BV$20/1000000 -> 0 | O14: ='Cap Table'!$BT$13 -> Series G | P14: =IF(VLOOKUP(O14,$G$6:$I$14,2,FALSE)<>0,HLOOKUP(O14,'Cap Table'!$H$13:$CA$18,6,FALSE),) -> 0 | Q14: =IF(VLOOKUP(O14,$G$6:$I$14,2,FALSE)<>0,HLOOKUP(O14,'Cap Table'!$H$13:$CA$18,5,FALSE),) -> 0 | R14: =IF(VLOOKUP(O14,$G$6:$I$14,2,FALSE)<>0,-OFFSET('Cap Table'!$H$13,27,-6+MATCH(O14,'Cap Table'!$13:$13,0))/1000000,) -> 0 | S14: =VLOOKUP(O14,$G$6:$I$14,3,FALSE) -> 0
C16: Returns Analysis - Participating | H16: Base Scenario
C17: Exit | D17: 0 | E17: =Seniority!CC80+(Seniority!CC80*('Transaction Expenses'!F6)+'Transaction Expenses'!D6/1000000) -> 0 | F17: =SUM(Seniority!CC80:CC81)+(SUM(Seniority!CC80:CC81)*('Transaction Expenses'!F6)+'Transaction Expenses'!D6/1000000) -> 0 | G17: =SUM(Seniority!CC80:CE82)+(SUM(Seniority!CC80:CE82)*('Transaction Expenses'!F6)+'Transaction Expenses'!D6/1000000) -> #DIV/0! | H17: =D9 -> #DIV/0! | I17: =H17*2 -> #DIV/0! | J17: =I17*2 -> #DIV/0! | K17: =J17*2 -> #DIV/0! | L17: =K17*2 -> #DIV/0!
C18: Variation from the base | D18: =D17/$H$17-1 -> #DIV/0! | E18: =E17/$H$17-1 -> #DIV/0! | F18: =F17/$H$17-1 -> #DIV/0! | G18: =G17/$H$17-1 -> #DIV/0! | H18: =H17/$H$17-1 -> #DIV/0! | I18: =I17/$H$17-1 -> #DIV/0! | J18: =J17/$H$17-1 -> #DIV/0! | K18: =K17/$H$17-1 -> #DIV/0! | L18: =L17/$H$17-1 -> #DIV/0!
C19: DTC proceeds | D19: =IF(D$17>$D$9,($D$10+($D$12*D$17)),($D$12*D$17)) -> #DIV/0! | E19: =IF(E$17>$D$9,($D$10+($D$12*E$17)),($D$12*E$17)) -> #DIV/0! | F19: =IF(F$17>$D$9,($D$10+($D$12*F$17)),($D$12*F$17)) -> #DIV/0! | G19: =IF(G$17>$D$9,($D$10+($D$12*G$17)),($D$12*G$17)) -> #DIV/0! | H19: =IF(H$17>$D$9,($D$10+($D$12*H$17)),($D$12*H$17)) -> #DIV/0! | I19: =IF(I$17>$D$9,($D$10+($D$12*I$17)),($D$12*I$17)) -> #DIV/0! | J19: =IF(J$17>$D$9,($D$10+($D$12*J$17)),($D$12*J$17)) -> #DIV/0! | K19: =IF(K$17>$D$9,($D$10+($D$12*K$17)),($D$12*K$17)) -> #DIV/0! | L19: =IF(L$17>$D$9,($D$10+($D$12*L$17)),($D$12*L$17)) -> #DIV/0!
C20: DTC return | D20: =D19/$D$7 -> #DIV/0! | E20: =E19/$D$7 -> #DIV/0! | F20: =F19/$D$7 -> #DIV/0! | G20: =G19/$D$7 -> #DIV/0! | H20: =H19/$D$7 -> #DIV/0! | I20: =I19/$D$7 -> #DIV/0! | J20: =J19/$D$7 -> #DIV/0! | K20: =K19/$D$7 -> #DIV/0! | L20: =L19/$D$7 -> #DIV/0!
